{"tag": "function", "depth": 1, "time": 1750089992.2254922, "data": {"name": "connect_device", "call_args": {"uri": "Android:///TPC7N18515001155"}, "start_time": 1750089986.4042468, "traceback": "Traceback (most recent call last):\n  File \"C:\\Python312\\Lib\\site-packages\\airtest\\core\\android\\adb.py\", line 341, in wait_for_device\n    self.cmd(\"wait-for-device\", timeout=timeout)\n  File \"C:\\Python312\\Lib\\site-packages\\airtest\\core\\android\\adb.py\", line 221, in cmd\n    stdout, stderr = proc_communicate_timeout(proc, timeout)\n                     ^^^^^^^^^^^^^^^^^^^^^^^^^^^^^^^^^^^^^^^\n  File \"C:\\Python312\\Lib\\site-packages\\airtest\\utils\\compat.py\", line 79, in proc_communicate_timeout\n    raise_from(exp, None)\n  File \"<string>\", line 3, in raise_from\nRuntimeError: Command ['C:\\\\Python312\\\\Lib\\\\site-packages\\\\airtest\\\\core\\\\android\\\\static\\\\adb\\\\windows\\\\adb.exe', '-s', 'TPC7N18515001155', 'wait-for-device'] timed out after 5 seconds: stdout['b'''], stderr['b''']\n\nThe above exception was the direct cause of the following exception:\n\nTraceback (most recent call last):\n  File \"C:\\Python312\\Lib\\site-packages\\airtest\\utils\\logwraper.py\", line 134, in wrapper\n    res = f(*args, **kwargs)\n          ^^^^^^^^^^^^^^^^^^\n  File \"C:\\Python312\\Lib\\site-packages\\airtest\\core\\api.py\", line 74, in connect_device\n    dev = init_device(platform, uuid, **params)\n          ^^^^^^^^^^^^^^^^^^^^^^^^^^^^^^^^^^^^^\n  File \"C:\\Python312\\Lib\\site-packages\\airtest\\core\\api.py\", line 42, in init_device\n    dev = cls(uuid, **kwargs)\n          ^^^^^^^^^^^^^^^^^^^\n  File \"C:\\Python312\\Lib\\site-packages\\airtest\\core\\android\\android.py\", line 59, in __init__\n    self.adb.wait_for_device()\n  File \"C:\\Python312\\Lib\\site-packages\\airtest\\core\\android\\adb.py\", line 343, in wait_for_device\n    raisefrom(DeviceConnectionError, \"device not ready\", e)\n  File \"C:\\Python312\\Lib\\site-packages\\airtest\\utils\\compat.py\", line 55, in raisefrom\n    raise_from(exc_type(message), exc)\n  File \"<string>\", line 3, in raise_from\nairtest.core.error.DeviceConnectionError: 'device not ready'\n", "end_time": 1750089992.2254922}}
